#VRML_SIM R2023b utf8


PROTO Car4wMulti2 [
  field SFVec3f    translation  0 0 0.04
  field SFRotation rotation     0 0 1 0
  field MFFloat    battery      [289800000 289800000 0]
  field SFString   controller   "CarSupMulti"
  field  SFString  name         "Car4wMulti2" 
]
{
  Robot {
    translation IS translation
    rotation IS rotation
    controller IS controller
    supervisor TRUE
    children [
      DEF BODY Shape {
        appearance PBRAppearance {
          baseColor 0.917647 0.145098 0.145098
          roughness 1
          metalness 0
        }
        geometry *BODY_GEOMETRY* {
          *BODY_SIZE*
        }
      }
      
      
      DEF BODY1 HingeJoint {
        jointParameters HingeJointParameters {
          axis 0 1 0
          anchor *BODY1_ANCHOR* 
          minStop -*BODY1_RIGID*     
          maxStop *BODY1_RIGID* 
        }
        endPoint Solid {
          translation *BODY1_ANCHOR* 
          rotation 1 0 0 0
          children [
            DEF BODY1 Shape {
              appearance PBRAppearance {
                baseColor 0.5 0.3 0.8
                roughness 1
                metalness 0
              }
              geometry *BODY1_GEOMETRY* {
                 *BODY1_SIZE*
              }
            }
            
            DEF WHEEL5 HingeJoint {
                jointParameters HingeJointParameters {
                axis 0 1 0
                anchor *WHEEL5_ANCHOR* 
                }
                device [
                RotationalMotor {
                    name "motor5"
                    maxTorque 5000
                    maxVelocity 26
                }
                ]
                endPoint Solid {
                translation *WHEEL5_ANCHOR* 
                rotation 1 0 0 1.5708
                children [
                    DEF WHEEL5 Shape {
                    appearance PBRAppearance {
                        baseColor 0.305882 0.898039 0.25098
                        roughness 1
                        metalness 0
                    }
                    geometry *WHEEL5_GEOMETRY* {
                        *WHEEL5_SIZE*
                    }
                    }
                ]
                name "wheel_5"
                contactMaterial "wheel"
                boundingObject USE WHEEL5
                physics Physics {
                    density 100
                }
                }
            }
    
            DEF WHEEL5SYM HingeJoint {
                jointParameters HingeJointParameters {
                axis 0 1 0
                anchor *WHEEL5SYM_ANCHOR* 
                }
                device [
                RotationalMotor {
                    name "motor5SYM"
                    maxTorque 5000
                    maxVelocity 26
                }
                ]
                endPoint Solid {
                translation *WHEEL5SYM_ANCHOR* 
                rotation 1 0 0 1.5708
                children [
                    DEF WHEEL5SYM Shape {
                    appearance PBRAppearance {
                        baseColor 0.305882 0.898039 0.25098
                        roughness 1
                        metalness 0
                    }
                    geometry *WHEEL5SYM_GEOMETRY* {
                        *WHEEL5SYM_SIZE*
                    }
                    }
                ]
                name "wheel_5SYM"
                contactMaterial "wheel"
                boundingObject USE WHEEL5SYM
                physics Physics {
                    density 100
                }
                }
            }
    
            DEF WHEEL6 HingeJoint {
                jointParameters HingeJointParameters {
                axis 0 1 0
                anchor *WHEEL6_ANCHOR* 
                }
                device [
                RotationalMotor {
                    name "motor6"
                    maxTorque 5000
                    maxVelocity 26
                }
                ]
                endPoint Solid {
                translation *WHEEL6_ANCHOR* 
                rotation 1 0 0 1.5708
                children [
                    DEF WHEEL6 Shape {
                    appearance PBRAppearance {
                        baseColor 0.305882 0.898039 0.25098
                        roughness 1
                        metalness 0
                    }
                    geometry *WHEEL6_GEOMETRY* {
                        *WHEEL6_SIZE*
                    }
                    }
                ]
                name "wheel_6"
                contactMaterial "wheel"
                boundingObject USE WHEEL6
                physics Physics {
                    density 100
                }
                }
            }
    
            DEF WHEEL6SYM HingeJoint {
                jointParameters HingeJointParameters {
                axis 0 1 0
                anchor *WHEEL6SYM_ANCHOR* 
                }
                device [
                RotationalMotor {
                    name "motor6SYM"
                    maxTorque 5000
                    maxVelocity 26
                }
                ]
                endPoint Solid {
                translation *WHEEL6SYM_ANCHOR* 
                rotation 1 0 0 1.5708
                children [
                    DEF WHEEL6SYM Shape {
                    appearance PBRAppearance {
                        baseColor 0.305882 0.898039 0.25098
                        roughness 1
                        metalness 0
                    }
                    geometry *WHEEL6SYM_GEOMETRY* {
                        *WHEEL6SYM_SIZE*
                    }
                    }
                ]
                name "wheel_6SYM"
                contactMaterial "wheel"
                boundingObject USE WHEEL6SYM
                physics Physics {
                    density 100
                }
                }
            }
    
            DEF WHEEL7 HingeJoint {
                jointParameters HingeJointParameters {
                axis 0 1 0
                anchor *WHEEL7_ANCHOR* 
                }
                device [
                RotationalMotor {
                    name "motor7"
                    maxTorque 5000
                    maxVelocity 26
                }
                ]
                endPoint Solid {
                translation *WHEEL7_ANCHOR* 
                rotation 1 0 0 1.5708
                children [
                    DEF WHEEL7 Shape {
                    appearance PBRAppearance {
                        baseColor 0.305882 0.898039 0.25098
                        roughness 1
                        metalness 0
                    }
                    geometry *WHEEL7_GEOMETRY* {
                        *WHEEL7_SIZE*
                    }
                    }
                ]
                name "wheel_7"
                contactMaterial "wheel"
                boundingObject USE WHEEL7
                physics Physics {
                    density 100
                }
                }
            }
    
            DEF WHEEL7SYM HingeJoint {
                jointParameters HingeJointParameters {
                axis 0 1 0
                anchor *WHEEL7SYM_ANCHOR* 
                }
                device [
                RotationalMotor {
                    name "motor7SYM"
                    maxTorque 5000
                    maxVelocity 26
                }
                ]
                endPoint Solid {
                translation *WHEEL7SYM_ANCHOR* 
                rotation 1 0 0 1.5708
                children [
                    DEF WHEEL7SYM Shape {
                    appearance PBRAppearance {
                        baseColor 0.305882 0.898039 0.25098
                        roughness 1
                        metalness 0
                    }
                    geometry *WHEEL7SYM_GEOMETRY* {
                        *WHEEL7SYM_SIZE*
                    }
                    }
                ]
                name "wheel_7SYM"
                contactMaterial "wheel"
                boundingObject USE WHEEL7SYM
                physics Physics {
                    density 100
                }
                }
            }
    
          ]
          name "body_1"
          contactMaterial "body_1"
          boundingObject USE BODY1
          physics Physics {
            density 300
          }
        }
      }
    
            DEF WHEEL1 HingeJoint {
                jointParameters HingeJointParameters {
                axis 0 1 0
                anchor *WHEEL1_ANCHOR* 
                }
                device [
                RotationalMotor {
                    name "motor1"
                    maxTorque 5000
                    maxVelocity 26
                }
                ]
                endPoint Solid {
                translation *WHEEL1_ANCHOR* 
                rotation 1 0 0 1.5708
                children [
                    DEF WHEEL1 Shape {
                    appearance PBRAppearance {
                        baseColor 0.305882 0.898039 0.25098
                        roughness 1
                        metalness 0
                    }
                    geometry *WHEEL1_GEOMETRY* {
                        *WHEEL1_SIZE*
                    }
                    }
                ]
                name "wheel_1"
                contactMaterial "wheel"
                boundingObject USE WHEEL1
                physics Physics {
                    density 100
                }
                }
            }
    
            DEF WHEEL1SYM HingeJoint {
                jointParameters HingeJointParameters {
                axis 0 1 0
                anchor *WHEEL1SYM_ANCHOR* 
                }
                device [
                RotationalMotor {
                    name "motor1SYM"
                    maxTorque 5000
                    maxVelocity 26
                }
                ]
                endPoint Solid {
                translation *WHEEL1SYM_ANCHOR* 
                rotation 1 0 0 1.5708
                children [
                    DEF WHEEL1SYM Shape {
                    appearance PBRAppearance {
                        baseColor 0.305882 0.898039 0.25098
                        roughness 1
                        metalness 0
                    }
                    geometry *WHEEL1SYM_GEOMETRY* {
                        *WHEEL1SYM_SIZE*
                    }
                    }
                ]
                name "wheel_1SYM"
                contactMaterial "wheel"
                boundingObject USE WHEEL1SYM
                physics Physics {
                    density 100
                }
                }
            }
    
            DEF WHEEL2 HingeJoint {
                jointParameters HingeJointParameters {
                axis 0 1 0
                anchor *WHEEL2_ANCHOR* 
                }
                device [
                RotationalMotor {
                    name "motor2"
                    maxTorque 5000
                    maxVelocity 26
                }
                ]
                endPoint Solid {
                translation *WHEEL2_ANCHOR* 
                rotation 1 0 0 1.5708
                children [
                    DEF WHEEL2 Shape {
                    appearance PBRAppearance {
                        baseColor 0.305882 0.898039 0.25098
                        roughness 1
                        metalness 0
                    }
                    geometry *WHEEL2_GEOMETRY* {
                        *WHEEL2_SIZE*
                    }
                    }
                ]
                name "wheel_2"
                contactMaterial "wheel"
                boundingObject USE WHEEL2
                physics Physics {
                    density 100
                }
                }
            }
    
            DEF WHEEL2SYM HingeJoint {
                jointParameters HingeJointParameters {
                axis 0 1 0
                anchor *WHEEL2SYM_ANCHOR* 
                }
                device [
                RotationalMotor {
                    name "motor2SYM"
                    maxTorque 5000
                    maxVelocity 26
                }
                ]
                endPoint Solid {
                translation *WHEEL2SYM_ANCHOR* 
                rotation 1 0 0 1.5708
                children [
                    DEF WHEEL2SYM Shape {
                    appearance PBRAppearance {
                        baseColor 0.305882 0.898039 0.25098
                        roughness 1
                        metalness 0
                    }
                    geometry *WHEEL2SYM_GEOMETRY* {
                        *WHEEL2SYM_SIZE*
                    }
                    }
                ]
                name "wheel_2SYM"
                contactMaterial "wheel"
                boundingObject USE WHEEL2SYM
                physics Physics {
                    density 100
                }
                }
            }
    
            DEF WHEEL3 HingeJoint {
                jointParameters HingeJointParameters {
                axis 0 1 0
                anchor *WHEEL3_ANCHOR* 
                }
                device [
                RotationalMotor {
                    name "motor3"
                    maxTorque 5000
                    maxVelocity 26
                }
                ]
                endPoint Solid {
                translation *WHEEL3_ANCHOR* 
                rotation 1 0 0 1.5708
                children [
                    DEF WHEEL3 Shape {
                    appearance PBRAppearance {
                        baseColor 0.305882 0.898039 0.25098
                        roughness 1
                        metalness 0
                    }
                    geometry *WHEEL3_GEOMETRY* {
                        *WHEEL3_SIZE*
                    }
                    }
                ]
                name "wheel_3"
                contactMaterial "wheel"
                boundingObject USE WHEEL3
                physics Physics {
                    density 100
                }
                }
            }
    
            DEF WHEEL3SYM HingeJoint {
                jointParameters HingeJointParameters {
                axis 0 1 0
                anchor *WHEEL3SYM_ANCHOR* 
                }
                device [
                RotationalMotor {
                    name "motor3SYM"
                    maxTorque 5000
                    maxVelocity 26
                }
                ]
                endPoint Solid {
                translation *WHEEL3SYM_ANCHOR* 
                rotation 1 0 0 1.5708
                children [
                    DEF WHEEL3SYM Shape {
                    appearance PBRAppearance {
                        baseColor 0.305882 0.898039 0.25098
                        roughness 1
                        metalness 0
                    }
                    geometry *WHEEL3SYM_GEOMETRY* {
                        *WHEEL3SYM_SIZE*
                    }
                    }
                ]
                name "wheel_3SYM"
                contactMaterial "wheel"
                boundingObject USE WHEEL3SYM
                physics Physics {
                    density 100
                }
                }
            }
    
            DEF WHEEL4 HingeJoint {
                jointParameters HingeJointParameters {
                axis 0 1 0
                anchor *WHEEL4_ANCHOR* 
                }
                device [
                RotationalMotor {
                    name "motor4"
                    maxTorque 5000
                    maxVelocity 26
                }
                ]
                endPoint Solid {
                translation *WHEEL4_ANCHOR* 
                rotation 1 0 0 1.5708
                children [
                    DEF WHEEL4 Shape {
                    appearance PBRAppearance {
                        baseColor 0.305882 0.898039 0.25098
                        roughness 1
                        metalness 0
                    }
                    geometry *WHEEL4_GEOMETRY* {
                        *WHEEL4_SIZE*
                    }
                    }
                ]
                name "wheel_4"
                contactMaterial "wheel"
                boundingObject USE WHEEL4
                physics Physics {
                    density 100
                }
                }
            }
    
            DEF WHEEL4SYM HingeJoint {
                jointParameters HingeJointParameters {
                axis 0 1 0
                anchor *WHEEL4SYM_ANCHOR* 
                }
                device [
                RotationalMotor {
                    name "motor4SYM"
                    maxTorque 5000
                    maxVelocity 26
                }
                ]
                endPoint Solid {
                translation *WHEEL4SYM_ANCHOR* 
                rotation 1 0 0 1.5708
                children [
                    DEF WHEEL4SYM Shape {
                    appearance PBRAppearance {
                        baseColor 0.305882 0.898039 0.25098
                        roughness 1
                        metalness 0
                    }
                    geometry *WHEEL4SYM_GEOMETRY* {
                        *WHEEL4SYM_SIZE*
                    }
                    }
                ]
                name "wheel_4SYM"
                contactMaterial "wheel"
                boundingObject USE WHEEL4SYM
                physics Physics {
                    density 100
                }
                }
            }
    

      DEF DS_RIGHT DistanceSensor {
        translation 0.1 -0.03 0
        rotation 0 0 1 -0.3
        children [
          Shape {
            appearance PBRAppearance {
              baseColor 0.184314 0.596078 0.847059
              roughness 1
              metalness 0
            }
            geometry Box {
              size 0.01 0.01 0.01
            }
          }
        ]
        name "ds_right"
      }
      DEF DS_LEFT DistanceSensor {
        translation 0.1 0.03 0
        rotation 0 0 1 0.3
        children [
          Shape {
            appearance PBRAppearance {
              baseColor 0.184314 0.596078 0.847059
              roughness 1
              metalness 0
            }
            geometry Box {
              size 0.01 0.01 0.01
            }
          }
        ]
        name "ds_left"
      }
      DEF COMPASS Compass {
      }
      DEF GPS GPS {
      }
      DEF GYRO Gyro {
      }
      DEF INERTIAL_UNIT InertialUnit {
      }
    ]
    name IS name
    boundingObject USE BODY
    physics Physics {
      density 300
    }
    controller "CarSupMulti"
    battery IS battery
  }
}