#VRML_SIM R2023b utf8
# license: Copyright Cyberbotics Ltd. Licensed for use only with Webots.
# license url: https://cyberbotics.com/webots_assets_license
# documentation url: https://webots.cloud/run?url=https://github.com/cyberbotics/webots/blob/released/projects/samples/tutorials/protos/FourWheelsRobot.proto
# keywords: robot/wheeled

PROTO CarConvOutput [
  field SFVec3f    translation  0 0 0.04
  field SFRotation rotation     0 0 1 0
  field SFFloat    bodyMass     1
  field SFString   controller   "CarSup2"
  field  SFString  name         "Car4wDS" 
]
{
  Robot {
    translation IS translation
    rotation IS rotation
    controller IS controller
    supervisor TRUE
    children [
      DEF BODY Shape {
        appearance PBRAppearance {
          baseColor 0.917647 0.145098 0.145098
          roughness 1
          metalness 0
        }
        geometry *BODY_GEOMETRY* {
          *BODY_SIZE*
        }
      }
      DEF WHEEL1 HingeJoint {
        jointParameters HingeJointParameters {
          axis 0 1 0
          anchor *FLWHEEL_ANCHOR* 
        }
        device [
          RotationalMotor {
            name "motor1"
          }
        ]
        endPoint Solid {
          translation *FLWHEEL_ANCHOR* 
          rotation 1 0 0 1.5708
          children [
            DEF WHEELFL Shape {
              appearance PBRAppearance {
                baseColor 0.305882 0.898039 0.25098
                roughness 1
                metalness 0
              }
              geometry *FLWHEEL_GEOMETRY* {
                *FLWHEEL_SIZE*
              }
            }
          ]
          name "FL_wheel"
          contactMaterial "FL_wheel"
          boundingObject USE WHEELFL
          physics Physics {
          }
        }
      }
      DEF WHEEL2 HingeJoint {
        jointParameters HingeJointParameters {
          axis 0 1 0
          anchor *FRWHEEL_ANCHOR* 
        }
        device [
          RotationalMotor {
            name "motor2"
          }
        ]
        endPoint Solid {
          translation *FRWHEEL_ANCHOR* 
          rotation 1 0 0 1.5708
          children [
            DEF WHEELFR Shape {
              appearance PBRAppearance {
                baseColor 0.305882 0.898039 0.25098
                roughness 1
                metalness 0
              }
              geometry *FRWHEEL_GEOMETRY* {
                *FRWHEEL_SIZE*
              }
            }
          ]
          name "FR_wheel"
          contactMaterial "FR_wheel"
          boundingObject USE WHEELFR
          physics Physics {
          }
        }
      }
      DEF WHEEL3 HingeJoint {
        jointParameters HingeJointParameters {
          axis 0 1 0
          anchor *BLWHEEL_ANCHOR* 
        }
        device [
          RotationalMotor {
            name "motor3"
          }
        ]
        endPoint Solid {
          translation *BLWHEEL_ANCHOR* 
          rotation 1 0 0 1.5708
          children [
            DEF WHEELBL Shape {
              appearance PBRAppearance {
                baseColor 0.305882 0.898039 0.25098
                roughness 1
                metalness 0
              }
              geometry *BLWHEEL_GEOMETRY* {
                *BLWHEEL_SIZE*
              }
            }
          ]
          name "BL_wheel"
          contactMaterial "BL_wheel"
          boundingObject USE WHEELBL
          physics Physics {
          }
        }
      }
      DEF WHEEL4 HingeJoint {
        jointParameters HingeJointParameters {
          axis 0 1 0
          anchor *BRWHEEL_ANCHOR* 
        }
        device [
          RotationalMotor {
            name "motor4"
          }
        ]
        endPoint Solid {
          translation *BRWHEEL_ANCHOR* 
          rotation 1 0 0 1.5708
          children [
            DEF WHEELBR Shape {
              appearance PBRAppearance {
                baseColor 0.305882 0.898039 0.25098
                roughness 1
                metalness 0
              }
              geometry *BRWHEEL_GEOMETRY* {
                *BRWHEEL_SIZE*
              }
            }
          ]
          name "BR_wheel"
          contactMaterial "BR_wheel"
          boundingObject USE WHEELBR
          physics Physics {
          }
        }
      }
      DEF DS_RIGHT DistanceSensor {
        translation 0.1 -0.03 0
        rotation 0 0 1 -0.3
        children [
          Shape {
            appearance PBRAppearance {
              baseColor 0.184314 0.596078 0.847059
              roughness 1
              metalness 0
            }
            geometry Box {
              size 0.01 0.01 0.01
            }
          }
        ]
        name "ds_right"
      }
      DEF DS_LEFT DistanceSensor {
        translation 0.1 0.03 0
        rotation 0 0 1 0.3
        children [
          Shape {
            appearance PBRAppearance {
              baseColor 0.184314 0.596078 0.847059
              roughness 1
              metalness 0
            }
            geometry Box {
              size 0.01 0.01 0.01
            }
          }
        ]
        name "ds_left"
      }
    ]
    name IS name
    boundingObject USE BODY
    physics Physics {
      density -1
      mass IS bodyMass
    }
    controller "CarSup2"
  }
}