#VRML_SIM R2023b utf8


PROTO Car4wMulti2 [
  field SFVec3f    translation  0 0 0.04
  field SFRotation rotation     0 0 1 0
  field MFFloat    battery      [289800000 289800000 0]
  field SFString   controller   "CarSupMulti"
  field  SFString  name         "Car4wMulti2" 
]
{
  Robot {
    translation IS translation
    rotation IS rotation
    controller IS controller
    supervisor TRUE
    children [
      DEF BODY Shape {
        appearance PBRAppearance {
          baseColor 0.917647 0.145098 0.145098
          roughness 1
          metalness 0
        }
        geometry Cylinder {
                         height 0.09351292699575425
               radius 0.19958372116088868

        }
      }
      
      
      DEF BODY1 HingeJoint {
        jointParameters HingeJointParameters {
          axis 0 1 0
          anchor 0.39802690446376804 0.0 0.0 
          minStop -.5     
          maxStop .5 
        }
        endPoint Solid {
          translation 0.39802690446376804 0.0 0.0 
          rotation 1 0 0 0
          children [
            DEF BODY1 Shape {
              appearance PBRAppearance {
                baseColor 0.5 0.3 0.8
                roughness 1
                metalness 0
              }
              geometry Cylinder {
                                height 0.1048623412847519
               radius 0.19844318330287936

              }
            }
            
            DEF WHEEL7 HingeJoint {
                jointParameters HingeJointParameters {
                axis 0 1 0
                anchor 0.19601297459355538 0.24615716934204104 -0.09543879121541977 
                }
                device [
                RotationalMotor {
                    name "motor7"
                    maxTorque 5000
                    maxVelocity 26
                }
                ]
                endPoint Solid {
                translation 0.19601297459355538 0.24615716934204104 -0.09543879121541977 
                rotation 1 0 0 1.5708
                children [
                    DEF WHEEL7 Shape {
                    appearance PBRAppearance {
                        baseColor 0.305882 0.898039 0.25098
                        roughness 1
                        metalness 0
                    }
                    geometry Sphere {
                                       radius 0.0866641104221344
               subdivision 1

                    }
                    }
                ]
                name "wheel_7"
                contactMaterial "wheel"
                boundingObject USE WHEEL7
                physics Physics {
                    density 100
                }
                }
            }
    
            DEF WHEEL7SYM HingeJoint {
                jointParameters HingeJointParameters {
                axis 0 1 0
                anchor 0.19601297459355538 -0.24615716934204104 -0.09543879121541977 
                }
                device [
                RotationalMotor {
                    name "motor7SYM"
                    maxTorque 5000
                    maxVelocity 26
                }
                ]
                endPoint Solid {
                translation 0.19601297459355538 -0.24615716934204104 -0.09543879121541977 
                rotation 1 0 0 1.5708
                children [
                    DEF WHEEL7SYM Shape {
                    appearance PBRAppearance {
                        baseColor 0.305882 0.898039 0.25098
                        roughness 1
                        metalness 0
                    }
                    geometry Sphere {
                                       radius 0.0866641104221344
               subdivision 1

                    }
                    }
                ]
                name "wheel_7SYM"
                contactMaterial "wheel"
                boundingObject USE WHEEL7SYM
                physics Physics {
                    density 100
                }
                }
            }
    
            DEF WHEEL8 HingeJoint {
                jointParameters HingeJointParameters {
                axis 0 1 0
                anchor -0.15480556926553202 0.21856592148542406 -0.07379870742559433 
                }
                device [
                RotationalMotor {
                    name "motor8"
                    maxTorque 5000
                    maxVelocity 26
                }
                ]
                endPoint Solid {
                translation -0.15480556926553202 0.21856592148542406 -0.07379870742559433 
                rotation 1 0 0 1.5708
                children [
                    DEF WHEEL8 Shape {
                    appearance PBRAppearance {
                        baseColor 0.305882 0.898039 0.25098
                        roughness 1
                        metalness 0
                    }
                    geometry Cylinder {
                                       height 0.03653866112232208
               radius 0.09014257609844208

                    }
                    }
                ]
                name "wheel_8"
                contactMaterial "wheel"
                boundingObject USE WHEEL8
                physics Physics {
                    density 100
                }
                }
            }
    
            DEF WHEEL8SYM HingeJoint {
                jointParameters HingeJointParameters {
                axis 0 1 0
                anchor -0.15480556926553202 -0.21856592148542406 -0.07379870742559433 
                }
                device [
                RotationalMotor {
                    name "motor8SYM"
                    maxTorque 5000
                    maxVelocity 26
                }
                ]
                endPoint Solid {
                translation -0.15480556926553202 -0.21856592148542406 -0.07379870742559433 
                rotation 1 0 0 1.5708
                children [
                    DEF WHEEL8SYM Shape {
                    appearance PBRAppearance {
                        baseColor 0.305882 0.898039 0.25098
                        roughness 1
                        metalness 0
                    }
                    geometry Cylinder {
                                       height 0.03653866112232208
               radius 0.09014257609844208

                    }
                    }
                ]
                name "wheel_8SYM"
                contactMaterial "wheel"
                boundingObject USE WHEEL8SYM
                physics Physics {
                    density 100
                }
                }
            }
    
            DEF WHEEL9 HingeJoint {
                jointParameters HingeJointParameters {
                axis 0 1 0
                anchor 0.12109585931871615 0.24460511505603794 -0.09346645921468735 
                }
                device [
                RotationalMotor {
                    name "motor9"
                    maxTorque 5000
                    maxVelocity 26
                }
                ]
                endPoint Solid {
                translation 0.12109585931871615 0.24460511505603794 -0.09346645921468735 
                rotation 1 0 0 1.5708
                children [
                    DEF WHEEL9 Shape {
                    appearance PBRAppearance {
                        baseColor 0.305882 0.898039 0.25098
                        roughness 1
                        metalness 0
                    }
                    geometry Sphere {
                                       radius 0.09876986920833589
               subdivision 1

                    }
                    }
                ]
                name "wheel_9"
                contactMaterial "wheel"
                boundingObject USE WHEEL9
                physics Physics {
                    density 100
                }
                }
            }
    
            DEF WHEEL9SYM HingeJoint {
                jointParameters HingeJointParameters {
                axis 0 1 0
                anchor 0.12109585931871615 -0.24460511505603794 -0.09346645921468735 
                }
                device [
                RotationalMotor {
                    name "motor9SYM"
                    maxTorque 5000
                    maxVelocity 26
                }
                ]
                endPoint Solid {
                translation 0.12109585931871615 -0.24460511505603794 -0.09346645921468735 
                rotation 1 0 0 1.5708
                children [
                    DEF WHEEL9SYM Shape {
                    appearance PBRAppearance {
                        baseColor 0.305882 0.898039 0.25098
                        roughness 1
                        metalness 0
                    }
                    geometry Sphere {
                                       radius 0.09876986920833589
               subdivision 1

                    }
                    }
                ]
                name "wheel_9SYM"
                contactMaterial "wheel"
                boundingObject USE WHEEL9SYM
                physics Physics {
                    density 100
                }
                }
            }
    
            DEF WHEEL10 HingeJoint {
                jointParameters HingeJointParameters {
                axis 0 1 0
                anchor 0.07836336081922078 0.23201837539672854 -0.09585220903158188 
                }
                device [
                RotationalMotor {
                    name "motor10"
                    maxTorque 5000
                    maxVelocity 26
                }
                ]
                endPoint Solid {
                translation 0.07836336081922078 0.23201837539672854 -0.09585220903158188 
                rotation 1 0 0 1.5708
                children [
                    DEF WHEEL10 Shape {
                    appearance PBRAppearance {
                        baseColor 0.305882 0.898039 0.25098
                        roughness 1
                        metalness 0
                    }
                    geometry Sphere {
                                       radius 0.09956703782081605
               subdivision 1

                    }
                    }
                ]
                name "wheel_10"
                contactMaterial "wheel"
                boundingObject USE WHEEL10
                physics Physics {
                    density 100
                }
                }
            }
    
            DEF WHEEL10SYM HingeJoint {
                jointParameters HingeJointParameters {
                axis 0 1 0
                anchor 0.07836336081922078 -0.23201837539672854 -0.09585220903158188 
                }
                device [
                RotationalMotor {
                    name "motor10SYM"
                    maxTorque 5000
                    maxVelocity 26
                }
                ]
                endPoint Solid {
                translation 0.07836336081922078 -0.23201837539672854 -0.09585220903158188 
                rotation 1 0 0 1.5708
                children [
                    DEF WHEEL10SYM Shape {
                    appearance PBRAppearance {
                        baseColor 0.305882 0.898039 0.25098
                        roughness 1
                        metalness 0
                    }
                    geometry Sphere {
                                       radius 0.09956703782081605
               subdivision 1

                    }
                    }
                ]
                name "wheel_10SYM"
                contactMaterial "wheel"
                boundingObject USE WHEEL10SYM
                physics Physics {
                    density 100
                }
                }
            }
    
            DEF WHEEL11 HingeJoint {
                jointParameters HingeJointParameters {
                axis 0 1 0
                anchor 0.16917980845188368 0.24294183254241947 -0.09634989112615586 
                }
                device [
                RotationalMotor {
                    name "motor11"
                    maxTorque 5000
                    maxVelocity 26
                }
                ]
                endPoint Solid {
                translation 0.16917980845188368 0.24294183254241947 -0.09634989112615586 
                rotation 1 0 0 1.5708
                children [
                    DEF WHEEL11 Shape {
                    appearance PBRAppearance {
                        baseColor 0.305882 0.898039 0.25098
                        roughness 1
                        metalness 0
                    }
                    geometry Sphere {
                                       radius 0.09465654075145721
               subdivision 1

                    }
                    }
                ]
                name "wheel_11"
                contactMaterial "wheel"
                boundingObject USE WHEEL11
                physics Physics {
                    density 100
                }
                }
            }
    
            DEF WHEEL11SYM HingeJoint {
                jointParameters HingeJointParameters {
                axis 0 1 0
                anchor 0.16917980845188368 -0.24294183254241947 -0.09634989112615586 
                }
                device [
                RotationalMotor {
                    name "motor11SYM"
                    maxTorque 5000
                    maxVelocity 26
                }
                ]
                endPoint Solid {
                translation 0.16917980845188368 -0.24294183254241947 -0.09634989112615586 
                rotation 1 0 0 1.5708
                children [
                    DEF WHEEL11SYM Shape {
                    appearance PBRAppearance {
                        baseColor 0.305882 0.898039 0.25098
                        roughness 1
                        metalness 0
                    }
                    geometry Sphere {
                                       radius 0.09465654075145721
               subdivision 1

                    }
                    }
                ]
                name "wheel_11SYM"
                contactMaterial "wheel"
                boundingObject USE WHEEL11SYM
                physics Physics {
                    density 100
                }
                }
            }
    
            DEF WHEEL12 HingeJoint {
                jointParameters HingeJointParameters {
                axis 0 1 0
                anchor 0.15213977071137139 0.23804984986782077 -0.10234023660421372 
                }
                device [
                RotationalMotor {
                    name "motor12"
                    maxTorque 5000
                    maxVelocity 26
                }
                ]
                endPoint Solid {
                translation 0.15213977071137139 0.23804984986782077 -0.10234023660421372 
                rotation 1 0 0 1.5708
                children [
                    DEF WHEEL12 Shape {
                    appearance PBRAppearance {
                        baseColor 0.305882 0.898039 0.25098
                        roughness 1
                        metalness 0
                    }
                    geometry Sphere {
                                       radius 0.08223556339740754
               subdivision 1

                    }
                    }
                ]
                name "wheel_12"
                contactMaterial "wheel"
                boundingObject USE WHEEL12
                physics Physics {
                    density 100
                }
                }
            }
    
            DEF WHEEL12SYM HingeJoint {
                jointParameters HingeJointParameters {
                axis 0 1 0
                anchor 0.15213977071137139 -0.23804984986782077 -0.10234023660421372 
                }
                device [
                RotationalMotor {
                    name "motor12SYM"
                    maxTorque 5000
                    maxVelocity 26
                }
                ]
                endPoint Solid {
                translation 0.15213977071137139 -0.23804984986782077 -0.10234023660421372 
                rotation 1 0 0 1.5708
                children [
                    DEF WHEEL12SYM Shape {
                    appearance PBRAppearance {
                        baseColor 0.305882 0.898039 0.25098
                        roughness 1
                        metalness 0
                    }
                    geometry Sphere {
                                       radius 0.08223556339740754
               subdivision 1

                    }
                    }
                ]
                name "wheel_12SYM"
                contactMaterial "wheel"
                boundingObject USE WHEEL12SYM
                physics Physics {
                    density 100
                }
                }
            }
    
          ]
          name "body_1"
          contactMaterial "body_1"
          boundingObject USE BODY1
          physics Physics {
            density 300
          }
        }
      }
    
            DEF WHEEL1 HingeJoint {
                jointParameters HingeJointParameters {
                axis 0 1 0
                anchor 0.187482634265632 0.24399120807647706 -0.07854320570826531 
                }
                device [
                RotationalMotor {
                    name "motor1"
                    maxTorque 5000
                    maxVelocity 26
                }
                ]
                endPoint Solid {
                translation 0.187482634265632 0.24399120807647706 -0.07854320570826531 
                rotation 1 0 0 1.5708
                children [
                    DEF WHEEL1 Shape {
                    appearance PBRAppearance {
                        baseColor 0.305882 0.898039 0.25098
                        roughness 1
                        metalness 0
                    }
                    geometry Sphere {
                                       radius 0.09948095500469209
               subdivision 1

                    }
                    }
                ]
                name "wheel_1"
                contactMaterial "wheel"
                boundingObject USE WHEEL1
                physics Physics {
                    density 100
                }
                }
            }
    
            DEF WHEEL1SYM HingeJoint {
                jointParameters HingeJointParameters {
                axis 0 1 0
                anchor 0.187482634265632 -0.24399120807647706 -0.07854320570826531 
                }
                device [
                RotationalMotor {
                    name "motor1SYM"
                    maxTorque 5000
                    maxVelocity 26
                }
                ]
                endPoint Solid {
                translation 0.187482634265632 -0.24399120807647706 -0.07854320570826531 
                rotation 1 0 0 1.5708
                children [
                    DEF WHEEL1SYM Shape {
                    appearance PBRAppearance {
                        baseColor 0.305882 0.898039 0.25098
                        roughness 1
                        metalness 0
                    }
                    geometry Sphere {
                                       radius 0.09948095500469209
               subdivision 1

                    }
                    }
                ]
                name "wheel_1SYM"
                contactMaterial "wheel"
                boundingObject USE WHEEL1SYM
                physics Physics {
                    density 100
                }
                }
            }
    
            DEF WHEEL2 HingeJoint {
                jointParameters HingeJointParameters {
                axis 0 1 0
                anchor 0.18377896863696608 0.2470070630311966 -0.0793683783710003 
                }
                device [
                RotationalMotor {
                    name "motor2"
                    maxTorque 5000
                    maxVelocity 26
                }
                ]
                endPoint Solid {
                translation 0.18377896863696608 0.2470070630311966 -0.0793683783710003 
                rotation 1 0 0 1.5708
                children [
                    DEF WHEEL2 Shape {
                    appearance PBRAppearance {
                        baseColor 0.305882 0.898039 0.25098
                        roughness 1
                        metalness 0
                    }
                    geometry Sphere {
                                       radius 0.08415286540985108
               subdivision 1

                    }
                    }
                ]
                name "wheel_2"
                contactMaterial "wheel"
                boundingObject USE WHEEL2
                physics Physics {
                    density 100
                }
                }
            }
    
            DEF WHEEL2SYM HingeJoint {
                jointParameters HingeJointParameters {
                axis 0 1 0
                anchor 0.18377896863696608 -0.2470070630311966 -0.0793683783710003 
                }
                device [
                RotationalMotor {
                    name "motor2SYM"
                    maxTorque 5000
                    maxVelocity 26
                }
                ]
                endPoint Solid {
                translation 0.18377896863696608 -0.2470070630311966 -0.0793683783710003 
                rotation 1 0 0 1.5708
                children [
                    DEF WHEEL2SYM Shape {
                    appearance PBRAppearance {
                        baseColor 0.305882 0.898039 0.25098
                        roughness 1
                        metalness 0
                    }
                    geometry Sphere {
                                       radius 0.08415286540985108
               subdivision 1

                    }
                    }
                ]
                name "wheel_2SYM"
                contactMaterial "wheel"
                boundingObject USE WHEEL2SYM
                physics Physics {
                    density 100
                }
                }
            }
    
            DEF WHEEL3 HingeJoint {
                jointParameters HingeJointParameters {
                axis 0 1 0
                anchor 0.19910811441111492 0.24862864315509797 -0.084122643917799 
                }
                device [
                RotationalMotor {
                    name "motor3"
                    maxTorque 5000
                    maxVelocity 26
                }
                ]
                endPoint Solid {
                translation 0.19910811441111492 0.24862864315509797 -0.084122643917799 
                rotation 1 0 0 1.5708
                children [
                    DEF WHEEL3 Shape {
                    appearance PBRAppearance {
                        baseColor 0.305882 0.898039 0.25098
                        roughness 1
                        metalness 0
                    }
                    geometry Sphere {
                                       radius 0.09240669310092926
               subdivision 1

                    }
                    }
                ]
                name "wheel_3"
                contactMaterial "wheel"
                boundingObject USE WHEEL3
                physics Physics {
                    density 100
                }
                }
            }
    
            DEF WHEEL3SYM HingeJoint {
                jointParameters HingeJointParameters {
                axis 0 1 0
                anchor 0.19910811441111492 -0.24862864315509797 -0.084122643917799 
                }
                device [
                RotationalMotor {
                    name "motor3SYM"
                    maxTorque 5000
                    maxVelocity 26
                }
                ]
                endPoint Solid {
                translation 0.19910811441111492 -0.24862864315509797 -0.084122643917799 
                rotation 1 0 0 1.5708
                children [
                    DEF WHEEL3SYM Shape {
                    appearance PBRAppearance {
                        baseColor 0.305882 0.898039 0.25098
                        roughness 1
                        metalness 0
                    }
                    geometry Sphere {
                                       radius 0.09240669310092926
               subdivision 1

                    }
                    }
                ]
                name "wheel_3SYM"
                contactMaterial "wheel"
                boundingObject USE WHEEL3SYM
                physics Physics {
                    density 100
                }
                }
            }
    
            DEF WHEEL4 HingeJoint {
                jointParameters HingeJointParameters {
                axis 0 1 0
                anchor 0.057747629094603785 0.24726479947566987 -0.08363296911120416 
                }
                device [
                RotationalMotor {
                    name "motor4"
                    maxTorque 5000
                    maxVelocity 26
                }
                ]
                endPoint Solid {
                translation 0.057747629094603785 0.24726479947566987 -0.08363296911120416 
                rotation 1 0 0 1.5708
                children [
                    DEF WHEEL4 Shape {
                    appearance PBRAppearance {
                        baseColor 0.305882 0.898039 0.25098
                        roughness 1
                        metalness 0
                    }
                    geometry Sphere {
                                       radius 0.09944694459438325
               subdivision 1

                    }
                    }
                ]
                name "wheel_4"
                contactMaterial "wheel"
                boundingObject USE WHEEL4
                physics Physics {
                    density 100
                }
                }
            }
    
            DEF WHEEL4SYM HingeJoint {
                jointParameters HingeJointParameters {
                axis 0 1 0
                anchor 0.057747629094603785 -0.24726479947566987 -0.08363296911120416 
                }
                device [
                RotationalMotor {
                    name "motor4SYM"
                    maxTorque 5000
                    maxVelocity 26
                }
                ]
                endPoint Solid {
                translation 0.057747629094603785 -0.24726479947566987 -0.08363296911120416 
                rotation 1 0 0 1.5708
                children [
                    DEF WHEEL4SYM Shape {
                    appearance PBRAppearance {
                        baseColor 0.305882 0.898039 0.25098
                        roughness 1
                        metalness 0
                    }
                    geometry Sphere {
                                       radius 0.09944694459438325
               subdivision 1

                    }
                    }
                ]
                name "wheel_4SYM"
                contactMaterial "wheel"
                boundingObject USE WHEEL4SYM
                physics Physics {
                    density 100
                }
                }
            }
    
            DEF WHEEL5 HingeJoint {
                jointParameters HingeJointParameters {
                axis 0 1 0
                anchor -0.019257088892896946 0.24949721693992616 -0.0859868471324444 
                }
                device [
                RotationalMotor {
                    name "motor5"
                    maxTorque 5000
                    maxVelocity 26
                }
                ]
                endPoint Solid {
                translation -0.019257088892896946 0.24949721693992616 -0.0859868471324444 
                rotation 1 0 0 1.5708
                children [
                    DEF WHEEL5 Shape {
                    appearance PBRAppearance {
                        baseColor 0.305882 0.898039 0.25098
                        roughness 1
                        metalness 0
                    }
                    geometry Sphere {
                                       radius 0.07150170087814331
               subdivision 1

                    }
                    }
                ]
                name "wheel_5"
                contactMaterial "wheel"
                boundingObject USE WHEEL5
                physics Physics {
                    density 100
                }
                }
            }
    
            DEF WHEEL5SYM HingeJoint {
                jointParameters HingeJointParameters {
                axis 0 1 0
                anchor -0.019257088892896946 -0.24949721693992616 -0.0859868471324444 
                }
                device [
                RotationalMotor {
                    name "motor5SYM"
                    maxTorque 5000
                    maxVelocity 26
                }
                ]
                endPoint Solid {
                translation -0.019257088892896946 -0.24949721693992616 -0.0859868471324444 
                rotation 1 0 0 1.5708
                children [
                    DEF WHEEL5SYM Shape {
                    appearance PBRAppearance {
                        baseColor 0.305882 0.898039 0.25098
                        roughness 1
                        metalness 0
                    }
                    geometry Sphere {
                                       radius 0.07150170087814331
               subdivision 1

                    }
                    }
                ]
                name "wheel_5SYM"
                contactMaterial "wheel"
                boundingObject USE WHEEL5SYM
                physics Physics {
                    density 100
                }
                }
            }
    
            DEF WHEEL6 HingeJoint {
                jointParameters HingeJointParameters {
                axis 0 1 0
                anchor 0.17829045722768344 0.23272875249385835 -0.09043541595339777 
                }
                device [
                RotationalMotor {
                    name "motor6"
                    maxTorque 5000
                    maxVelocity 26
                }
                ]
                endPoint Solid {
                translation 0.17829045722768344 0.23272875249385835 -0.09043541595339777 
                rotation 1 0 0 1.5708
                children [
                    DEF WHEEL6 Shape {
                    appearance PBRAppearance {
                        baseColor 0.305882 0.898039 0.25098
                        roughness 1
                        metalness 0
                    }
                    geometry Sphere {
                                       radius 0.09465553760528565
               subdivision 1

                    }
                    }
                ]
                name "wheel_6"
                contactMaterial "wheel"
                boundingObject USE WHEEL6
                physics Physics {
                    density 100
                }
                }
            }
    
            DEF WHEEL6SYM HingeJoint {
                jointParameters HingeJointParameters {
                axis 0 1 0
                anchor 0.17829045722768344 -0.23272875249385835 -0.09043541595339777 
                }
                device [
                RotationalMotor {
                    name "motor6SYM"
                    maxTorque 5000
                    maxVelocity 26
                }
                ]
                endPoint Solid {
                translation 0.17829045722768344 -0.23272875249385835 -0.09043541595339777 
                rotation 1 0 0 1.5708
                children [
                    DEF WHEEL6SYM Shape {
                    appearance PBRAppearance {
                        baseColor 0.305882 0.898039 0.25098
                        roughness 1
                        metalness 0
                    }
                    geometry Sphere {
                                       radius 0.09465553760528565
               subdivision 1

                    }
                    }
                ]
                name "wheel_6SYM"
                contactMaterial "wheel"
                boundingObject USE WHEEL6SYM
                physics Physics {
                    density 100
                }
                }
            }
    

      DEF DS_RIGHT DistanceSensor {
        translation 0.1 -0.03 0
        rotation 0 0 1 -0.3
        children [
          Shape {
            appearance PBRAppearance {
              baseColor 0.184314 0.596078 0.847059
              roughness 1
              metalness 0
            }
            geometry Box {
              size 0.01 0.01 0.01
            }
          }
        ]
        name "ds_right"
      }
      DEF DS_LEFT DistanceSensor {
        translation 0.1 0.03 0
        rotation 0 0 1 0.3
        children [
          Shape {
            appearance PBRAppearance {
              baseColor 0.184314 0.596078 0.847059
              roughness 1
              metalness 0
            }
            geometry Box {
              size 0.01 0.01 0.01
            }
          }
        ]
        name "ds_left"
      }
      DEF COMPASS Compass {
      }
      DEF GPS GPS {
      }
      DEF GYRO Gyro {
      }
      DEF INERTIAL_UNIT InertialUnit {
      }
    ]
    name IS name
    boundingObject USE BODY
    physics Physics {
      density 300
    }
    controller "CarSupMulti"
    battery IS battery
  }
}