#VRML_SIM R2023b utf8
# license: Copyright Cyberbotics Ltd. Licensed for use only with Webots.
# license url: https://cyberbotics.com/webots_assets_license
# documentation url: https://webots.cloud/run?url=https://github.com/cyberbotics/webots/blob/released/projects/samples/tutorials/protos/FourWheelsRobot.proto
# keywords: robot/wheeled

PROTO Car4wMulti2 [
  field SFVec3f    translation  0 0 0.04
  field SFRotation rotation     0 0 1 0
  field SFFloat    bodyMass     1
  field SFString   controller   "CarSupMulti"
  field  SFString  name         "Car4wMulti2" 
]
{
  Robot {
    translation IS translation
    rotation IS rotation
    controller IS controller
    supervisor TRUE
    children [
      DEF BODY Shape {
        appearance PBRAppearance {
          baseColor 0.917647 0.145098 0.145098
          roughness 1
          metalness 0
        }
        geometry Box {
                         size 0.0948574334383011 0.18880263566970829 0.07654056325554848

        }
      }
      
      
            DEF WHEEL1 HingeJoint {
                jointParameters HingeJointParameters {
                axis 0 1 0
                anchor -0.028764964005867637 0.09842678271234037 -0.05457285113632679 
                }
                device [
                RotationalMotor {
                    name "motor1"
                    maxTorque 100
                    maxVelocity 26
                }
                ]
                endPoint Solid {
                translation -0.028764964005867637 0.09842678271234037 -0.05457285113632679 
                rotation 1 0 0 1.5708
                children [
                    DEF WHEEL1 Shape {
                    appearance PBRAppearance {
                        baseColor 0.305882 0.898039 0.25098
                        roughness 1
                        metalness 0
                    }
                    geometry Box {
                                       size 0.013989352062344551 0.07424967229366303 0.03516700893640518

                    }
                    }
                ]
                name "wheel_1"
                contactMaterial "wheel_1"
                boundingObject USE WHEEL1
                physics Physics {
                }
                }
            }
    
            DEF WHEEL1SYM HingeJoint {
                jointParameters HingeJointParameters {
                axis 0 1 0
                anchor -0.028764964005867637 -0.09842678271234037 -0.05457285113632679 
                }
                device [
                RotationalMotor {
                    name "motor1SYM"
                    maxTorque 100
                    maxVelocity 26
                }
                ]
                endPoint Solid {
                translation -0.028764964005867637 -0.09842678271234037 -0.05457285113632679 
                rotation 1 0 0 1.5708
                children [
                    DEF WHEEL1SYM Shape {
                    appearance PBRAppearance {
                        baseColor 0.305882 0.898039 0.25098
                        roughness 1
                        metalness 0
                    }
                    geometry Box {
                                       size 0.013989352062344551 0.07424967229366303 0.03516700893640518

                    }
                    }
                ]
                name "wheel_1SYM"
                contactMaterial "wheel_1SYM"
                boundingObject USE WHEEL1SYM
                physics Physics {
                }
                }
            }
    
            DEF WHEEL2 HingeJoint {
                jointParameters HingeJointParameters {
                axis 0 1 0
                anchor -0.027302403282594992 0.09940845221281053 -0.03769938088953495 
                }
                device [
                RotationalMotor {
                    name "motor2"
                    maxTorque 100
                    maxVelocity 26
                }
                ]
                endPoint Solid {
                translation -0.027302403282594992 0.09940845221281053 -0.03769938088953495 
                rotation 1 0 0 1.5708
                children [
                    DEF WHEEL2 Shape {
                    appearance PBRAppearance {
                        baseColor 0.305882 0.898039 0.25098
                        roughness 1
                        metalness 0
                    }
                    geometry Box {
                                       size 0.09722332358360292 0.08285308837890626 0.07242230474948884

                    }
                    }
                ]
                name "wheel_2"
                contactMaterial "wheel_2"
                boundingObject USE WHEEL2
                physics Physics {
                }
                }
            }
    
            DEF WHEEL2SYM HingeJoint {
                jointParameters HingeJointParameters {
                axis 0 1 0
                anchor -0.027302403282594992 -0.09940845221281053 -0.03769938088953495 
                }
                device [
                RotationalMotor {
                    name "motor2SYM"
                    maxTorque 100
                    maxVelocity 26
                }
                ]
                endPoint Solid {
                translation -0.027302403282594992 -0.09940845221281053 -0.03769938088953495 
                rotation 1 0 0 1.5708
                children [
                    DEF WHEEL2SYM Shape {
                    appearance PBRAppearance {
                        baseColor 0.305882 0.898039 0.25098
                        roughness 1
                        metalness 0
                    }
                    geometry Box {
                                       size 0.09722332358360292 0.08285308837890626 0.07242230474948884

                    }
                    }
                ]
                name "wheel_2SYM"
                contactMaterial "wheel_2SYM"
                boundingObject USE WHEEL2SYM
                physics Physics {
                }
                }
            }
    
            DEF WHEEL3 HingeJoint {
                jointParameters HingeJointParameters {
                axis 0 1 0
                anchor 0.04138375766157943 0.10282666310667993 -0.04284407414495945 
                }
                device [
                RotationalMotor {
                    name "motor3"
                    maxTorque 100
                    maxVelocity 26
                }
                ]
                endPoint Solid {
                translation 0.04138375766157943 0.10282666310667993 -0.04284407414495945 
                rotation 1 0 0 1.5708
                children [
                    DEF WHEEL3 Shape {
                    appearance PBRAppearance {
                        baseColor 0.305882 0.898039 0.25098
                        roughness 1
                        metalness 0
                    }
                    geometry Box {
                                       size 0.06455079913139344 0.035984959304332736 0.08599370300769807

                    }
                    }
                ]
                name "wheel_3"
                contactMaterial "wheel_3"
                boundingObject USE WHEEL3
                physics Physics {
                }
                }
            }
    
            DEF WHEEL3SYM HingeJoint {
                jointParameters HingeJointParameters {
                axis 0 1 0
                anchor 0.04138375766157943 -0.10282666310667993 -0.04284407414495945 
                }
                device [
                RotationalMotor {
                    name "motor3SYM"
                    maxTorque 100
                    maxVelocity 26
                }
                ]
                endPoint Solid {
                translation 0.04138375766157943 -0.10282666310667993 -0.04284407414495945 
                rotation 1 0 0 1.5708
                children [
                    DEF WHEEL3SYM Shape {
                    appearance PBRAppearance {
                        baseColor 0.305882 0.898039 0.25098
                        roughness 1
                        metalness 0
                    }
                    geometry Box {
                                       size 0.06455079913139344 0.035984959304332736 0.08599370300769807

                    }
                    }
                ]
                name "wheel_3SYM"
                contactMaterial "wheel_3SYM"
                boundingObject USE WHEEL3SYM
                physics Physics {
                }
                }
            }
    
            DEF WHEEL4 HingeJoint {
                jointParameters HingeJointParameters {
                axis 0 1 0
                anchor -0.015317169347144334 0.12474930584430696 -0.06738772161304951 
                }
                device [
                RotationalMotor {
                    name "motor4"
                    maxTorque 100
                    maxVelocity 26
                }
                ]
                endPoint Solid {
                translation -0.015317169347144334 0.12474930584430696 -0.06738772161304951 
                rotation 1 0 0 1.5708
                children [
                    DEF WHEEL4 Shape {
                    appearance PBRAppearance {
                        baseColor 0.305882 0.898039 0.25098
                        roughness 1
                        metalness 0
                    }
                    geometry Sphere {
                                       radius 0.03246338784694672
               subdivision 1

                    }
                    }
                ]
                name "wheel_4"
                contactMaterial "wheel_4"
                boundingObject USE WHEEL4
                physics Physics {
                }
                }
            }
    
            DEF WHEEL4SYM HingeJoint {
                jointParameters HingeJointParameters {
                axis 0 1 0
                anchor -0.015317169347144334 -0.12474930584430696 -0.06738772161304951 
                }
                device [
                RotationalMotor {
                    name "motor4SYM"
                    maxTorque 100
                    maxVelocity 26
                }
                ]
                endPoint Solid {
                translation -0.015317169347144334 -0.12474930584430696 -0.06738772161304951 
                rotation 1 0 0 1.5708
                children [
                    DEF WHEEL4SYM Shape {
                    appearance PBRAppearance {
                        baseColor 0.305882 0.898039 0.25098
                        roughness 1
                        metalness 0
                    }
                    geometry Sphere {
                                       radius 0.03246338784694672
               subdivision 1

                    }
                    }
                ]
                name "wheel_4SYM"
                contactMaterial "wheel_4SYM"
                boundingObject USE WHEEL4SYM
                physics Physics {
                }
                }
            }
    

      DEF DS_RIGHT DistanceSensor {
        translation 0.1 -0.03 0
        rotation 0 0 1 -0.3
        children [
          Shape {
            appearance PBRAppearance {
              baseColor 0.184314 0.596078 0.847059
              roughness 1
              metalness 0
            }
            geometry Box {
              size 0.01 0.01 0.01
            }
          }
        ]
        name "ds_right"
      }
      DEF DS_LEFT DistanceSensor {
        translation 0.1 0.03 0
        rotation 0 0 1 0.3
        children [
          Shape {
            appearance PBRAppearance {
              baseColor 0.184314 0.596078 0.847059
              roughness 1
              metalness 0
            }
            geometry Box {
              size 0.01 0.01 0.01
            }
          }
        ]
        name "ds_left"
      }
      DEF GPS GPS {
      }
    ]
    name IS name
    boundingObject USE BODY
    physics Physics {
      density -1
      mass IS bodyMass
    }
    controller "CarSupMulti"
  }
}