#VRML_SIM R2023b utf8
# license: Copyright Cyberbotics Ltd. Licensed for use only with Webots.
# license url: https://cyberbotics.com/webots_assets_license
# documentation url: https://webots.cloud/run?url=https://github.com/cyberbotics/webots/blob/released/projects/samples/tutorials/protos/FourWheelsRobot.proto
# keywords: robot/wheeled

PROTO Car4wBB [
  field SFVec3f    translation  0 0 0.04
  field SFRotation rotation     0 0 1 0
  field SFFloat    bodyMass     1
  field SFString   controller   "CarSupBB"
  field  SFString  name         "Car4wBB" 
]
{
  Robot {
    translation IS translation
    rotation IS rotation
    controller IS controller
    supervisor TRUE
    children [
      DEF BODY Shape {
        appearance PBRAppearance {
          baseColor 0.917647 0.145098 0.145098
          roughness 1
          metalness 0
        }
        geometry Box {
          size 0.2 0.1 0.05
        }
      }
      DEF BODY2 SliderJoint {
        jointParameters HingeJointParameters {
          axis 0 1 0
          anchor 0.2 0 0
        }
        endPoint Solid {
          translation 0.2 0 0
          rotation 1 0 0 0
          children [
            DEF BODY2 Shape {
              appearance PBRAppearance {
                baseColor 0.5 0.3 0.8
                roughness 1
                metalness 0
              }
              geometry Box {
                size 0.2 0.1 0.05
              }
            }
          ]
          boundingObject USE BODY2
        }
      }
      DEF WHEELBB1 HingeJoint {
        jointParameters HingeJointParameters {
          axis 0 1 0
          anchor 0.25 0.06 0
        }
        device [
          RotationalMotor {
            name "motorBB1"
          }
        ]
        endPoint Solid {
          translation 0.25 0.06 0
          rotation 1 0 0 1.5708
          children [
            DEF WHEELBB1 Shape {
              appearance PBRAppearance {
                baseColor 0.305882 0.898039 0.25098
                roughness 1
                metalness 0
              }
              geometry Box {
                size 0.1 0.1 0.02
              }
            }
          ]
          boundingObject USE WHEELBB1
          physics Physics {
          }
        }
      }
      DEF WHEELBB2 HingeJoint {
        jointParameters HingeJointParameters {
          axis 0 1 0
          anchor 0.25 -0.06 0
        }
        device [
          RotationalMotor {
            name "motorBB2"
          }
        ]
        endPoint Solid {
          translation 0.25 -0.06 0
          rotation 1 0 0 1.5708
          children [
            DEF WHEELBB2 Shape {
              appearance PBRAppearance {
                baseColor 0.305882 0.898039 0.25098
                roughness 1
                metalness 0
              }
              geometry Box {
                size 0.1 0.1 0.02
              }
            }
          ]
          boundingObject USE WHEELBB2
          physics Physics {
          }
        }
      }
      DEF WHEEL1 HingeJoint {
        jointParameters HingeJointParameters {
          axis 0 1 0
          anchor 0.05 0.06 0
        }
        device [
          RotationalMotor {
            name "motor1"
          }
        ]
        endPoint Solid {
          translation 0.05 0.06 0
          rotation 1 0 0 1.5708
          children [
            DEF WHEELFL Shape {
              appearance PBRAppearance {
                baseColor 0.305882 0.898039 0.25098
                roughness 1
                metalness 0
              }
              geometry Cylinder {
                height 0.02
                radius 0.06
              }
            }
          ]
          boundingObject USE WHEELFL
          physics Physics {
          }
        }
      }
      DEF WHEEL2 HingeJoint {
        jointParameters HingeJointParameters {
          axis 0 1 0
          anchor 0.05 -0.06 0
        }
        device [
          RotationalMotor {
            name "motor2"
          }
        ]
        endPoint Solid {
          translation 0.05 -0.06 0
          rotation 1 0 0 1.5708
          children [
            DEF WHEELFR Shape {
              appearance PBRAppearance {
                baseColor 0.305882 0.898039 0.25098
                roughness 1
                metalness 0
              }
              geometry Cylinder {
                height 0.02
                radius 0.06
              }
            }
          ]
          name "solid(1)"
          boundingObject USE WHEELFR
          physics Physics {
          }
        }
      }
      DEF WHEEL3 HingeJoint {
        jointParameters HingeJointParameters {
          axis 0 1 0
          anchor -0.05 0.06 0
        }
        device [
          RotationalMotor {
            name "motor3"
          }
        ]
        endPoint Solid {
          translation -0.05 0.06 0
          rotation 1 0 0 1.5708
          children [
            DEF WHEELBL Shape {
              appearance PBRAppearance {
                baseColor 0.305882 0.898039 0.25098
                roughness 1
                metalness 0
              }
              geometry Box {
                size 0.08 0.08 0.02
              }
            }
          ]
          name "solid(2)"
          boundingObject USE WHEELBL
          physics Physics {
          }
        }
      }
      DEF WHEEL4 HingeJoint {
        jointParameters HingeJointParameters {
          axis 0 1 0
          anchor -0.05 -0.06 0
        }
        device [
          RotationalMotor {
            name "motor4"
          }
        ]
        endPoint Solid {
          translation -0.05 -0.06 0
          rotation 1 0 0 1.5708
          children [
            DEF WHEELBR Shape {
              appearance PBRAppearance {
                baseColor 0.305882 0.898039 0.25098
                roughness 1
                metalness 0
              }
              geometry Box {
                size 0.08 0.08 0.02
              }
            }
          ]
          name "solid(3)"
          boundingObject USE WHEELBR
          physics Physics {
          }
        }
      }
      DEF DS_RIGHT DistanceSensor {
        translation 0.1 -0.03 0
        rotation 0 0 1 -0.3
        children [
          Shape {
            appearance PBRAppearance {
              baseColor 0.184314 0.596078 0.847059
              roughness 1
              metalness 0
            }
            geometry Box {
              size 0.01 0.01 0.01
            }
          }
        ]
        name "ds_right"
      }
      DEF DS_LEFT DistanceSensor {
        translation 0.1 0.03 0
        rotation 0 0 1 0.3
        children [
          Shape {
            appearance PBRAppearance {
              baseColor 0.184314 0.596078 0.847059
              roughness 1
              metalness 0
            }
            geometry Box {
              size 0.01 0.01 0.01
            }
          }
        ]
        name "ds_left"
      }
    ]
    name IS name
    boundingObject USE BODY
    physics Physics {
      density -1
      mass IS bodyMass
    }
    controller "CarSup2"
  }
}

