#VRML_SIM R2023b utf8


PROTO Car4wMulti2 [
  field SFVec3f    translation  0 0 0.04
  field SFRotation rotation     0 0 1 0
  field MFFloat    battery      [289800000 289800000 0]
  field SFString   controller   "CarSupMulti"
  field  SFString  name         "Car4wMulti2" 
]
{
  Robot {
    translation IS translation
    rotation IS rotation
    controller IS controller
    supervisor TRUE
    children [
      DEF BODY Shape {
        appearance PBRAppearance {
          baseColor 0.917647 0.145098 0.145098
          roughness 1
          metalness 0
        }
        geometry Box {
                         size 0.051422166731208564 0.18649818003177643 0.07502251565456391

        }
      }
      
      
      DEF BODY1 HingeJoint {
        jointParameters HingeJointParameters {
          axis 0 1 0
          anchor 0.16579751665703957 0.0 0.0 
          minStop -.001     
          maxStop .001 
        }
        endPoint Solid {
          translation 0.16579751665703957 0.0 0.0 
          rotation 1 0 0 0
          children [
            DEF BODY1 Shape {
              appearance PBRAppearance {
                baseColor 0.5 0.3 0.8
                roughness 1
                metalness 0
              }
              geometry Cylinder {
                                height 0.08036726415157319
               radius 0.14008643329143528

              }
            }
            
            DEF WHEEL5 HingeJoint {
                jointParameters HingeJointParameters {
                axis 0 1 0
                anchor 0.09489910791494512 0.17529031932353978 -0.08635855525732042 
                }
                device [
                RotationalMotor {
                    name "motor5"
                    maxTorque 5000
                    maxVelocity 26
                }
                ]
                endPoint Solid {
                translation 0.09489910791494512 0.17529031932353978 -0.08635855525732042 
                rotation 1 0 0 1.5708
                children [
                    DEF WHEEL5 Shape {
                    appearance PBRAppearance {
                        baseColor 0.305882 0.898039 0.25098
                        roughness 1
                        metalness 0
                    }
                    geometry Sphere {
                                       radius 0.022253832817077636
               subdivision 1

                    }
                    }
                ]
                name "wheel_5"
                contactMaterial "wheel"
                boundingObject USE WHEEL5
                physics Physics {
                    density 100
                }
                }
            }
    
            DEF WHEEL5SYM HingeJoint {
                jointParameters HingeJointParameters {
                axis 0 1 0
                anchor 0.09489910791494512 -0.17529031932353978 -0.08635855525732042 
                }
                device [
                RotationalMotor {
                    name "motor5SYM"
                    maxTorque 5000
                    maxVelocity 26
                }
                ]
                endPoint Solid {
                translation 0.09489910791494512 -0.17529031932353978 -0.08635855525732042 
                rotation 1 0 0 1.5708
                children [
                    DEF WHEEL5SYM Shape {
                    appearance PBRAppearance {
                        baseColor 0.305882 0.898039 0.25098
                        roughness 1
                        metalness 0
                    }
                    geometry Sphere {
                                       radius 0.022253832817077636
               subdivision 1

                    }
                    }
                ]
                name "wheel_5SYM"
                contactMaterial "wheel"
                boundingObject USE WHEEL5SYM
                physics Physics {
                    density 100
                }
                }
            }
    
            DEF WHEEL6 HingeJoint {
                jointParameters HingeJointParameters {
                axis 0 1 0
                anchor 0.016801187880652796 0.14472229294478897 -0.0643162938952446 
                }
                device [
                RotationalMotor {
                    name "motor6"
                    maxTorque 5000
                    maxVelocity 26
                }
                ]
                endPoint Solid {
                translation 0.016801187880652796 0.14472229294478897 -0.0643162938952446 
                rotation 1 0 0 1.5708
                children [
                    DEF WHEEL6 Shape {
                    appearance PBRAppearance {
                        baseColor 0.305882 0.898039 0.25098
                        roughness 1
                        metalness 0
                    }
                    geometry Cylinder {
                                       height 0.09458864331245423
               radius 0.09485652089118958

                    }
                    }
                ]
                name "wheel_6"
                contactMaterial "wheel"
                boundingObject USE WHEEL6
                physics Physics {
                    density 100
                }
                }
            }
    
            DEF WHEEL6SYM HingeJoint {
                jointParameters HingeJointParameters {
                axis 0 1 0
                anchor 0.016801187880652796 -0.14472229294478897 -0.0643162938952446 
                }
                device [
                RotationalMotor {
                    name "motor6SYM"
                    maxTorque 5000
                    maxVelocity 26
                }
                ]
                endPoint Solid {
                translation 0.016801187880652796 -0.14472229294478897 -0.0643162938952446 
                rotation 1 0 0 1.5708
                children [
                    DEF WHEEL6SYM Shape {
                    appearance PBRAppearance {
                        baseColor 0.305882 0.898039 0.25098
                        roughness 1
                        metalness 0
                    }
                    geometry Cylinder {
                                       height 0.09458864331245423
               radius 0.09485652089118958

                    }
                    }
                ]
                name "wheel_6SYM"
                contactMaterial "wheel"
                boundingObject USE WHEEL6SYM
                physics Physics {
                    density 100
                }
                }
            }
    
            DEF WHEEL7 HingeJoint {
                jointParameters HingeJointParameters {
                axis 0 1 0
                anchor -0.08202028966684945 0.1610744029283524 -0.057474016249179846 
                }
                device [
                RotationalMotor {
                    name "motor7"
                    maxTorque 5000
                    maxVelocity 26
                }
                ]
                endPoint Solid {
                translation -0.08202028966684945 0.1610744029283524 -0.057474016249179846 
                rotation 1 0 0 1.5708
                children [
                    DEF WHEEL7 Shape {
                    appearance PBRAppearance {
                        baseColor 0.305882 0.898039 0.25098
                        roughness 1
                        metalness 0
                    }
                    geometry Box {
                                       size 0.029702944159507756 0.07000573098659515 0.06728777348995209

                    }
                    }
                ]
                name "wheel_7"
                contactMaterial "wheel"
                boundingObject USE WHEEL7
                physics Physics {
                    density 100
                }
                }
            }
    
            DEF WHEEL7SYM HingeJoint {
                jointParameters HingeJointParameters {
                axis 0 1 0
                anchor -0.08202028966684945 -0.1610744029283524 -0.057474016249179846 
                }
                device [
                RotationalMotor {
                    name "motor7SYM"
                    maxTorque 5000
                    maxVelocity 26
                }
                ]
                endPoint Solid {
                translation -0.08202028966684945 -0.1610744029283524 -0.057474016249179846 
                rotation 1 0 0 1.5708
                children [
                    DEF WHEEL7SYM Shape {
                    appearance PBRAppearance {
                        baseColor 0.305882 0.898039 0.25098
                        roughness 1
                        metalness 0
                    }
                    geometry Box {
                                       size 0.029702944159507756 0.07000573098659515 0.06728777348995209

                    }
                    }
                ]
                name "wheel_7SYM"
                contactMaterial "wheel"
                boundingObject USE WHEEL7SYM
                physics Physics {
                    density 100
                }
                }
            }
    
          ]
          name "body_1"
          contactMaterial "body_1"
          boundingObject USE BODY1
          physics Physics {
            density 300
          }
        }
      }
    
            DEF WHEEL1 HingeJoint {
                jointParameters HingeJointParameters {
                axis 0 1 0
                anchor -0.010459649587189535 0.14060051888227462 -0.02961112663149834 
                }
                device [
                RotationalMotor {
                    name "motor1"
                    maxTorque 5000
                    maxVelocity 26
                }
                ]
                endPoint Solid {
                translation -0.010459649587189535 0.14060051888227462 -0.02961112663149834 
                rotation 1 0 0 1.5708
                children [
                    DEF WHEEL1 Shape {
                    appearance PBRAppearance {
                        baseColor 0.305882 0.898039 0.25098
                        roughness 1
                        metalness 0
                    }
                    geometry Box {
                                       size 0.03566353142261505 0.03334794282913208 0.06309681117534638

                    }
                    }
                ]
                name "wheel_1"
                contactMaterial "wheel"
                boundingObject USE WHEEL1
                physics Physics {
                    density 100
                }
                }
            }
    
            DEF WHEEL1SYM HingeJoint {
                jointParameters HingeJointParameters {
                axis 0 1 0
                anchor -0.010459649587189535 -0.14060051888227462 -0.02961112663149834 
                }
                device [
                RotationalMotor {
                    name "motor1SYM"
                    maxTorque 5000
                    maxVelocity 26
                }
                ]
                endPoint Solid {
                translation -0.010459649587189535 -0.14060051888227462 -0.02961112663149834 
                rotation 1 0 0 1.5708
                children [
                    DEF WHEEL1SYM Shape {
                    appearance PBRAppearance {
                        baseColor 0.305882 0.898039 0.25098
                        roughness 1
                        metalness 0
                    }
                    geometry Box {
                                       size 0.03566353142261505 0.03334794282913208 0.06309681117534638

                    }
                    }
                ]
                name "wheel_1SYM"
                contactMaterial "wheel"
                boundingObject USE WHEEL1SYM
                physics Physics {
                    density 100
                }
                }
            }
    
            DEF WHEEL2 HingeJoint {
                jointParameters HingeJointParameters {
                axis 0 1 0
                anchor 0.003272926515345992 0.10361949801445007 -0.04646447807550431 
                }
                device [
                RotationalMotor {
                    name "motor2"
                    maxTorque 5000
                    maxVelocity 26
                }
                ]
                endPoint Solid {
                translation 0.003272926515345992 0.10361949801445007 -0.04646447807550431 
                rotation 1 0 0 1.5708
                children [
                    DEF WHEEL2 Shape {
                    appearance PBRAppearance {
                        baseColor 0.305882 0.898039 0.25098
                        roughness 1
                        metalness 0
                    }
                    geometry Box {
                                       size 0.04595842629671097 0.0942377781867981 0.08698218286037446

                    }
                    }
                ]
                name "wheel_2"
                contactMaterial "wheel"
                boundingObject USE WHEEL2
                physics Physics {
                    density 100
                }
                }
            }
    
            DEF WHEEL2SYM HingeJoint {
                jointParameters HingeJointParameters {
                axis 0 1 0
                anchor 0.003272926515345992 -0.10361949801445007 -0.04646447807550431 
                }
                device [
                RotationalMotor {
                    name "motor2SYM"
                    maxTorque 5000
                    maxVelocity 26
                }
                ]
                endPoint Solid {
                translation 0.003272926515345992 -0.10361949801445007 -0.04646447807550431 
                rotation 1 0 0 1.5708
                children [
                    DEF WHEEL2SYM Shape {
                    appearance PBRAppearance {
                        baseColor 0.305882 0.898039 0.25098
                        roughness 1
                        metalness 0
                    }
                    geometry Box {
                                       size 0.04595842629671097 0.0942377781867981 0.08698218286037446

                    }
                    }
                ]
                name "wheel_2SYM"
                contactMaterial "wheel"
                boundingObject USE WHEEL2SYM
                physics Physics {
                    density 100
                }
                }
            }
    
            DEF WHEEL3 HingeJoint {
                jointParameters HingeJointParameters {
                axis 0 1 0
                anchor -0.006278231024799061 0.11376732885837555 -0.04673374146223069 
                }
                device [
                RotationalMotor {
                    name "motor3"
                    maxTorque 5000
                    maxVelocity 26
                }
                ]
                endPoint Solid {
                translation -0.006278231024799061 0.11376732885837555 -0.04673374146223069 
                rotation 1 0 0 1.5708
                children [
                    DEF WHEEL3 Shape {
                    appearance PBRAppearance {
                        baseColor 0.305882 0.898039 0.25098
                        roughness 1
                        metalness 0
                    }
                    geometry Sphere {
                                       radius 0.07958815336227418
               subdivision 1

                    }
                    }
                ]
                name "wheel_3"
                contactMaterial "wheel"
                boundingObject USE WHEEL3
                physics Physics {
                    density 100
                }
                }
            }
    
            DEF WHEEL3SYM HingeJoint {
                jointParameters HingeJointParameters {
                axis 0 1 0
                anchor -0.006278231024799061 -0.11376732885837555 -0.04673374146223069 
                }
                device [
                RotationalMotor {
                    name "motor3SYM"
                    maxTorque 5000
                    maxVelocity 26
                }
                ]
                endPoint Solid {
                translation -0.006278231024799061 -0.11376732885837555 -0.04673374146223069 
                rotation 1 0 0 1.5708
                children [
                    DEF WHEEL3SYM Shape {
                    appearance PBRAppearance {
                        baseColor 0.305882 0.898039 0.25098
                        roughness 1
                        metalness 0
                    }
                    geometry Sphere {
                                       radius 0.07958815336227418
               subdivision 1

                    }
                    }
                ]
                name "wheel_3SYM"
                contactMaterial "wheel"
                boundingObject USE WHEEL3SYM
                physics Physics {
                    density 100
                }
                }
            }
    
            DEF WHEEL4 HingeJoint {
                jointParameters HingeJointParameters {
                axis 0 1 0
                anchor -0.014243564470717028 0.10708364993333816 -0.05350601702928544 
                }
                device [
                RotationalMotor {
                    name "motor4"
                    maxTorque 5000
                    maxVelocity 26
                }
                ]
                endPoint Solid {
                translation -0.014243564470717028 0.10708364993333816 -0.05350601702928544 
                rotation 1 0 0 1.5708
                children [
                    DEF WHEEL4 Shape {
                    appearance PBRAppearance {
                        baseColor 0.305882 0.898039 0.25098
                        roughness 1
                        metalness 0
                    }
                    geometry Sphere {
                                       radius 0.09642051696777344
               subdivision 1

                    }
                    }
                ]
                name "wheel_4"
                contactMaterial "wheel"
                boundingObject USE WHEEL4
                physics Physics {
                    density 100
                }
                }
            }
    
            DEF WHEEL4SYM HingeJoint {
                jointParameters HingeJointParameters {
                axis 0 1 0
                anchor -0.014243564470717028 -0.10708364993333816 -0.05350601702928544 
                }
                device [
                RotationalMotor {
                    name "motor4SYM"
                    maxTorque 5000
                    maxVelocity 26
                }
                ]
                endPoint Solid {
                translation -0.014243564470717028 -0.10708364993333816 -0.05350601702928544 
                rotation 1 0 0 1.5708
                children [
                    DEF WHEEL4SYM Shape {
                    appearance PBRAppearance {
                        baseColor 0.305882 0.898039 0.25098
                        roughness 1
                        metalness 0
                    }
                    geometry Sphere {
                                       radius 0.09642051696777344
               subdivision 1

                    }
                    }
                ]
                name "wheel_4SYM"
                contactMaterial "wheel"
                boundingObject USE WHEEL4SYM
                physics Physics {
                    density 100
                }
                }
            }
    

      DEF DS_RIGHT DistanceSensor {
        translation 0.1 -0.03 0
        rotation 0 0 1 -0.3
        children [
          Shape {
            appearance PBRAppearance {
              baseColor 0.184314 0.596078 0.847059
              roughness 1
              metalness 0
            }
            geometry Box {
              size 0.01 0.01 0.01
            }
          }
        ]
        name "ds_right"
      }
      DEF DS_LEFT DistanceSensor {
        translation 0.1 0.03 0
        rotation 0 0 1 0.3
        children [
          Shape {
            appearance PBRAppearance {
              baseColor 0.184314 0.596078 0.847059
              roughness 1
              metalness 0
            }
            geometry Box {
              size 0.01 0.01 0.01
            }
          }
        ]
        name "ds_left"
      }
      DEF COMPASS Compass {
      }
      DEF GPS GPS {
      }
      DEF GYRO Gyro {
      }
      DEF INERTIAL_UNIT InertialUnit {
      }
    ]
    name IS name
    boundingObject USE BODY
    physics Physics {
      density 300
    }
    controller "CarSupMulti"
    battery IS battery
  }
}